Workbook

Sheet Assumptions
A1: 关键假设 Key Assumptions — 能源
A2: 参数 Parameter | B2: 值 Value | C2: 单位 | D2: 说明
A3: 基年收入 Base revenue | B3: 37068.1 | C3: 千元
A4: 毛利率 Gross margin | B4: 0.6895
A5: 费用率 Opex % | B5: 0.208
A6: 所得税率 Tax rate | B6: 0.2675
A7: 资本开支率 Capex % | B7: 0.073
A8: 折旧年限 Dep. years | B8: 7 | C8: 年
A9: 应收周转 DSO | B9: 39 | C9: 天
A10: 存货周转 DIO | B10: 46 | C10: 天
A11: 应付周转 DPO | B11: 42 | C11: 天
A12: 利率 Interest rate | B12: 0.0481
A13: WACC | B13: 0.1123
A14: 永续增长 Terminal growth | B14: 0.0281
A15: 股本 Shares | B15: 2369 | C15: 千股
A16: 期初现金 Opening cash | B16: 4830.09
A17: 期初固定资产原值 | B17: 10564.4
A18: 期初累计折旧 | B18: 2912.28
A19: 期初有息负债 | B19: 6635.05
A20: 残值率 Salvage % | B20: 0.1244
A21: 毛利率年提升 GM ramp/yr | B21: 0.0184
A22: 固定费用 Fixed opex | B22: 2243.66
A23: 退出倍数 Exit EV/EBIT | B23: 7.3 | C23: x
A24: 收入增速 2024 Growth | B24: 0.244
A25: 收入增速 2025 Growth | B25: 0.2025
A26: 收入增速 2026 Growth | B26: 0.1312
A27: 收入增速 2027 Growth | B27: 0.2358
A28: 收入增速 2028 Growth | B28: 0.2585
A29: 还本 2024 Debt repayment | B29: 487.44
A30: 还本 2025 Debt repayment | B30: 687.14
A31: 还本 2026 Debt repayment | B31: 573.86
A32: 还本 2027 Debt repayment | B32: 399.72
A33: 还本 2028 Debt repayment | B33: 1041.05
A35: ★ 会计口径约定 House conventions（务必遵循）
A36: • 折旧按【期初原值】计提（非期末）：Depreciation = 期初原值 / 折旧年限。
A37: • 折旧考虑残值：Depreciation = (期初原值 × (1−残值率)) / 折旧年限。
A38: • 利息按【期初与期末负债的平均】计提：Interest = (期初+期末)/2 × 利率。
A39: • 期间费用 = 收入 × 费用率 + 固定费用（含一笔固定管理费）。
A40: • 毛利率逐年提升：第 t 年毛利率 = 基准毛利率 + GM ramp ×(t−1)。
A41: • 终值采用【退出倍数法】：TV = 末期EBIT × 退出倍数（非永续增长法）。
...

Sheet Revenue
A1: 收入预测 Revenue Forecast
A2: 项目 \ 年度 | B2: 期初 t0 | C2: 2024 | D2: 2025 | E2: 2026 | F2: 2027 | G2: 2028
A3: 营业收入 Revenue | B3: 37068.1 | C3: =B3*(1+Assumptions!B24) | D3: =C3*(1+Assumptions!B25) | E3: =D3*(1+Assumptions!B26) | F3: =E3*(1+Assumptions!B27) | G3: =F3*(1+Assumptions!B28)

Sheet PPE
A1: 固定资产与折旧 PP&E & Depreciation
A2: 项目 \ 年度 | B2: 期初 t0 | C2: 2024 | D2: 2025 | E2: 2026 | F2: 2027 | G2: 2028
A3: 期初原值 Gross begin | C3: =B5 | D3: =C5 | E3: =D5 | F3: =E5 | G3: =F5
A4: 资本开支 Capex | C4: =Revenue!C3*Assumptions!B7 | D4: =MAX(Revenue!D3*Assumptions!B7,C6) | E4: =MAX(Revenue!E3*Assumptions!B7,D6) | F4: =MAX(Revenue!F3*Assumptions!B7,E6) | G4: =MAX(Revenue!G3*Assumptions!B7,F6)
A5: 期末原值 Gross end | B5: 10564.4 | C5: =C3+C4 | D5: =D3+D4 | E5: =E3+E4 | F5: =F3+F4 | G5: =G3+G4
A6: 本期折旧 Depreciation | C6: =C3*(1-Assumptions!B20)/Assumptions!B8 | D6: =D3*(1-Assumptions!B20)/Assumptions!B8 | E6: =E3*(1-Assumptions!B20)/Assumptions!B8 | F6: =F3*(1-Assumptions!B20)/Assumptions!B8 | G6: =G3*(1-Assumptions!B20)/Assumptions!B8
A7: 累计折旧 Accum. dep | B7: 2912.28 | C7: =B7+C6 | D7: =C7+D6 | E7: =D7+E6 | F7: =E7+F6 | G7: =F7+G6
A8: 净值 Net PP&E | B8: =B5-B7 | C8: =C5-C7 | D8: =D5-D7 | E8: =E5-E7 | F8: =F5-F7 | G8: =G5-G7

Sheet IncomeStatement
A1: 利润表 Income Statement
A2: 项目 \ 年度 | B2: 期初 t0 | C2: 2024 | D2: 2025 | E2: 2026 | F2: 2027 | G2: 2028
A3: 营业收入 Revenue | C3: =Revenue!C3 | D3: =Revenue!D3 | E3: =Revenue!E3 | F3: =Revenue!F3 | G3: =Revenue!G3
A4: 营业成本 COGS | C4: =C3*(1-(Assumptions!B4+Assumptions!B21*0)) | D4: =D3*(1-(Assumptions!B4+Assumptions!B21*1)) | E4: =E3*(1-(Assumptions!B4+Assumptions!B21*2)) | F4: =F3*(1-(Assumptions!B4+Assumptions!B21*3)) | G4: =G3*(1-(Assumptions!B4+Assumptions!B21*4))
A5: 毛利 Gross profit | C5: =C3-C4 | D5: =D3-D4 | E5: =E3-E4 | F5: =F3-F4 | G5: =G3-G4
A6: 期间费用 Opex | C6: =C3*Assumptions!B5+Assumptions!B22 | D6: =D3*Assumptions!B5+Assumptions!B22 | E6: =E3*Assumptions!B5+Assumptions!B22 | F6: =F3*Assumptions!B5+Assumptions!B22 | G6: =G3*Assumptions!B5+Assumptions!B22
A7: 折旧摊销 D&A | C7: =PPE!C6 | D7: =PPE!D6 | E7: =PPE!E6 | F7: =PPE!F6 | G7: =PPE!G6
A8: 息税前利润 EBIT | C8: =C5-C6-C7 | D8: =D5-D6-D7 | E8: =E5-E6-E7 | F8: =F5-F6-F7 | G8: =G5-G6-G7
A9: 利息费用 Interest | C9: =(DebtSchedule!C3+DebtSchedule!C5)/2*Assumptions!B12 | D9: =(DebtSchedule!D3+DebtSchedule!D5)/2*Assumptions!B12 | E9: =(DebtSchedule!E3+DebtSchedule!E5)/2*Assumptions!B12 | F9: =(DebtSchedule!F3+DebtSchedule!F5)/2*Assumptions!B12 | G9: =(DebtSchedule!G3+DebtSchedule!G5)/2*Assumptions!B12
A10: 税前利润 EBT | C10: =C8-C9 | D10: =D8-D9 | E10: =E8-E9 | F10: =F8-F9 | G10: =G8-G9
A11: 所得税 Tax | C11: =MAX(C10,0)*Assumptions!B6 | D11: =MAX(D10,0)*Assumptions!B6 | E11: =MAX(E10,0)*Assumptions!B6 | F11: =MAX(F10,0)*Assumptions!B6 | G11: =MAX(G10,0)*Assumptions!B6
A12: 净利润 Net income | C12: =C10-C11 | D12: =D10-D11 | E12: =E10-E11 | F12: =F10-F11 | G12: =G10-G11

Sheet DebtSchedule
A1: 债务计划 Debt Schedule
A2: 项目 \ 年度 | B2: 期初 t0 | C2: 2024 | D2: 2025 | E2: 2026 | F2: 2027 | G2: 2028
A3: 期初负债 Debt begin | C3: =B5 | D3: =C5 | E3: =D5 | F3: =E5 | G3: =F5
A4: 还本 Repayment | C4: =Assumptions!B29 | D4: =Assumptions!B30 | E4: =Assumptions!B31 | F4: =Assumptions!B32 | G4: =Assumptions!B33
A5: 期末负债 Debt end | B5: 6635.05 | C5: =C3-C4 | D5: =D3-D4 | E5: =E3-E4 | F5: =F3-F4 | G5: =G3-G4

Sheet WorkingCapital
A1: 营运资本 Working Capital
A2: 项目 \ 年度 | B2: 期初 t0 | C2: 2024 | D2: 2025 | E2: 2026 | F2: 2027 | G2: 2028
A3: 应收账款 AR | B3: 3960.7 | C3: =IncomeStatement!C3*Assumptions!B9/365 | D3: =IncomeStatement!D3*Assumptions!B9/365 | E3: =IncomeStatement!E3*Assumptions!B9/365 | F3: =IncomeStatement!F3*Assumptions!B9/365 | G3: =IncomeStatement!G3*Assumptions!B9/365
A4: 存货 Inventory | B4: 1450.53 | C4: =IncomeStatement!C4*Assumptions!B10/365 | D4: =IncomeStatement!D4*Assumptions!B10/365 | E4: =IncomeStatement!E4*Assumptions!B10/365 | F4: =IncomeStatement!F4*Assumptions!B10/365 | G4: =IncomeStatement!G4*Assumptions!B10/365
A5: 应付账款 AP | B5: 1324.4 | C5: =IncomeStatement!C4*Assumptions!B11/365 | D5: =IncomeStatement!D4*Assumptions!B11/365 | E5: =IncomeStatement!E4*Assumptions!B11/365 | F5: =IncomeStatement!F4*Assumptions!B11/365 | G5: =IncomeStatement!G4*Assumptions!B11/365
A6: 净营运资本 NWC | B6: =B3+B4-B5 | C6: =C3+C4-C5 | D6: =D3+D4-D5 | E6: =E3+E4-E5 | F6: =F3+F4-F5 | G6: =G3+G4-G5
A7: NWC变动 ΔNWC | C7: =C6-B6 | D7: =D6-C6 | E7: =E6-D6 | F7: =F6-E6 | G7: =G6-F6

Sheet CashFlow
A1: 现金流量表（间接法）Cash Flow (Indirect)
A2: 项目 \ 年度 | B2: 期初 t0 | C2: 2024 | D2: 2025 | E2: 2026 | F2: 2027 | G2: 2028
A3: 净利润 Net income | C3: =IncomeStatement!C12 | D3: =IncomeStatement!D12 | E3: =IncomeStatement!E12 | F3: =IncomeStatement!F12 | G3: =IncomeStatement!G12
A4: 加:折旧摊销 +D&A | C4: =PPE!C6 | D4: =PPE!D6 | E4: =PPE!E6 | F4: =PPE!F6 | G4: =PPE!G6
A5: 减:ΔNWC -ΔNWC | C5: =-WorkingCapital!C7 | D5: =-WorkingCapital!D7 | E5: =-WorkingCapital!E7 | F5: =-WorkingCapital!F7 | G5: =-WorkingCapital!G7
A6: 经营活动现金流 CFO | C6: =C3+C4+C5 | D6: =D3+D4+D5 | E6: =E3+E4+E5 | F6: =F3+F4+F5 | G6: =G3+G4+G5
A7: 资本开支 Capex | C7: =-PPE!C4 | D7: =-PPE!D4 | E7: =-PPE!E4 | F7: =-PPE!F4 | G7: =-PPE!G4
A8: 投资活动现金流 CFI | C8: =C7 | D8: =D7 | E8: =E7 | F8: =F7 | G8: =G7
A9: 偿还债务 Debt repay | C9: =-DebtSchedule!C4 | D9: =-DebtSchedule!D4 | E9: =-DebtSchedule!E4 | F9: =-DebtSchedule!F4 | G9: =-DebtSchedule!G4
A10: 筹资活动现金流 CFF | C10: =C9 | D10: =D9 | E10: =E9 | F10: =F9 | G10: =G9
A11: 现金净变动 Net Δcash | C11: =C6+C8+C10 | D11: =D6+D8+D10 | E11: =E6+E8+E10 | F11: =F6+F8+F10 | G11: =G6+G8+G10
A12: 期初现金 Cash begin | C12: =B13 | D12: =C13 | E12: =D13 | F12: =E13 | G12: =F13
A13: 期末现金 Cash end | B13: 4830.09 | C13: =C12+C11 | D13: =D12+D11 | E13: =E12+E11 | F13: =F12+F11 | G13: =G12+G11

Sheet BalanceSheet
A1: 资产负债表 Balance Sheet
A2: 项目 \ 年度 | B2: 期初 t0 | C2: 2024 | D2: 2025 | E2: 2026 | F2: 2027 | G2: 2028
A3: 现金 Cash | B3: 4830.09 | C3: =CashFlow!C13 | D3: =CashFlow!D13 | E3: =CashFlow!E13 | F3: =CashFlow!F13 | G3: =CashFlow!G13
A4: 应收 AR | B4: 3960.7 | C4: =WorkingCapital!C3 | D4: =WorkingCapital!D3 | E4: =WorkingCapital!E3 | F4: =WorkingCapital!F3 | G4: =WorkingCapital!G3
A5: 存货 Inventory | B5: 1450.53 | C5: =WorkingCapital!C4 | D5: =WorkingCapital!D4 | E5: =WorkingCapital!E4 | F5: =WorkingCapital!F4 | G5: =WorkingCapital!G4
A6: 净固定资产 Net PP&E | B6: 7652.12 | C6: =PPE!C8 | D6: =PPE!D8 | E6: =PPE!E8 | F6: =PPE!F8 | G6: =PPE!G8
A7: 资产合计 Total assets | B7: =B3+B4+B5+B6 | C7: =C3+C4+C5+C6 | D7: =D3+D4+D5+D6 | E7: =E3+E4+E5+E6 | F7: =F3+F4+F5+F6 | G7: =G3+G4+G5+G6
A8: 应付 AP | B8: 1324.4 | C8: =WorkingCapital!C5 | D8: =WorkingCapital!D5 | E8: =WorkingCapital!E5 | F8: =WorkingCapital!F5 | G8: =WorkingCapital!G5
A9: 有息负债 Debt | B9: 6635.05 | C9: =DebtSchedule!C5 | D9: =DebtSchedule!D5 | E9: =DebtSchedule!E5 | F9: =DebtSchedule!F5 | G9: =DebtSchedule!G5
A10: 负债合计 Total liab | B10: =B8+B9 | C10: =C8+C9 | D10: =D8+D9 | E10: =E8+E9 | F10: =F8+F9 | G10: =G8+G9
A11: 所有者权益 Equity | B11: 9933.99 | C11: =B11+IncomeStatement!C12 | D11: =C11+IncomeStatement!D12 | E11: =D11+IncomeStatement!E12 | F11: =E11+IncomeStatement!F12 | G11: =F11+IncomeStatement!G12
A12: 负债+权益 Total L&E | B12: =B10+B11 | C12: =C10+C11 | D12: =D10+D11 | E12: =E10+E11 | F12: =F10+F11 | G12: =G10+G11
A13: 平衡校验 Check(=0) | B13: =B7-B12 | C13: =C7-C12 | D13: =D7-D12 | E13: =E7-E12 | F13: =F7-F12 | G13: =G7-G12

Sheet DCF
A1: 现金流折现估值 DCF Valuation
A2: 项目 \ 年度 | B2: 期初 t0 | C2: 2024 | D2: 2025 | E2: 2026 | F2: 2027 | G2: 2028
A3: EBIT | C3: =IncomeStatement!C8 | D3: =IncomeStatement!D8 | E3: =IncomeStatement!E8 | F3: =IncomeStatement!F8 | G3: =IncomeStatement!G8
A4: NOPAT=EBIT×(1-tax) | C4: =C3*(1-Assumptions!B6) | D4: =D3*(1-Assumptions!B6) | E4: =E3*(1-Assumptions!B6) | F4: =F3*(1-Assumptions!B6) | G4: =G3*(1-Assumptions!B6)
A5: 加:D&A | C5: =PPE!C6 | D5: =PPE!D6 | E5: =PPE!E6 | F5: =PPE!F6 | G5: =PPE!G6
A6: 减:Capex | C6: =-PPE!C4 | D6: =-PPE!D4 | E6: =-PPE!E4 | F6: =-PPE!F4 | G6: =-PPE!G4
A7: 减:ΔNWC | C7: =-WorkingCapital!C7 | D7: =-WorkingCapital!D7 | E7: =-WorkingCapital!E7 | F7: =-WorkingCapital!F7 | G7: =-WorkingCapital!G7
A8: 无杠杆自由现金流 FCFF | C8: =C4+C5+C6+C7 | D8: =D4+D5+D6+D7 | E8: =E4+E5+E6+E7 | F8: =F4+F5+F6+F7 | G8: =G4+G5+G6+G7
A9: 折现因子 DF | C9: =1/(1+Assumptions!B13)^(1-0.5) | D9: =1/(1+Assumptions!B13)^(2-0.5) | E9: =1/(1+Assumptions!B13)^(3-0.5) | F9: =1/(1+Assumptions!B13)^(4-0.5) | G9: =1/(1+Assumptions!B13)^(5-0.5)
A10: FCF现值 PV | C10: =C8*C9 | D10: =D8*D9 | E10: =E8*E9 | F10: =F8*F9 | G10: =G8*G9
A12: 预测期PV合计 Σ PV(FCF) | B12: =SUM(C10:G10)
A13: 终值 Terminal value | B13: =G3*Assumptions!B23
A14: 终值现值 PV(TV) | B14: =B13*G9
A15: 企业价值 Enterprise value | B15: =B12+B14
A16: 净负债 Net debt | B16: =Assumptions!B19-Assumptions!B16
A17: 股权价值 Equity value | B17: =B15-B16
A18: 每股价值 Value per share | B18: =B17/Assumptions!B15

Sheet 旧版测算_废弃
A1: ⚠ DEPRECATED — 请勿引用此表 / do not reference
A2: 项目 Item | B2: 金额 Amount | C2: 备注 Note | D2: 日期
A3: 杂项 | B3: 34010.49 | C3: check later
A4: 杂项 | B4: 24323.82 | C4: old
A5: 杂项 | B5: 39429.14 | C5: check later
A6: 杂项 | B6: 68961.04 | C6: 废弃
A7: 调整 | B7: 80781.01 | C7: 废弃
A8: 预留 | B8: 45362.2 | C8: check later
A9: 预留 | B9: 62506.15
A10: 杂项 | B10: 6869.42 | C10: check later
A11: TBD | B11: 85202.76 | C11: 废弃
A12: 杂项 | B12: 61148.53 | C12: 废弃
A13: 预留 | B13: 62033.37 | C13: old
A14: TBD | B14: 40736.39 | C14: old
A15: 杂项 | B15: 86183.99 | C15: check later

Sheet Archive_2019
A1: ⚠ DEPRECATED — 请勿引用此表 / do not reference
A2: 项目 Item | B2: 金额 Amount | C2: 备注 Note | D2: 日期
A3: 杂项 | B3: 6302.48 | C3: check later
A4: Misc | B4: 6116.91 | C4: check later
A5: 调整 | B5: 9065.98 | C5: old
A6: 调整 | B6: 42484.67 | C6: 废弃
A7: 杂项 | B7: 47670.71 | C7: check later
A8: 预留 | B8: 9510.62 | C8: old
A9: 杂项 | B9: 2258.86 | C9: 废弃
A10: TBD | B10: 41834.96
A11: 调整 | B11: 22228.55 | C11: check later
A12: Misc | B12: 59776.32 | C12: check later
A13: 调整 | B13: 2648.42 | C13: old
A14: 调整 | B14: 31753.45 | C14: check later
A15: Misc | B15: 36670.91
A16: 预留 | B16: 46955.46 | C16: old

Sheet Notes_DoNotUse
A1: ⚠ DEPRECATED — 请勿引用此表 / do not reference
A2: 项目 Item | B2: 金额 Amount | C2: 备注 Note | D2: 日期
A3: 杂项 | B3: 13980.99
A4: 调整 | B4: 3116.58 | C4: old
A5: 调整 | B5: 46671.18 | C5: old
A6: 预留 | B6: 41796.72 | C6: check later
A7: 调整 | B7: 61155.39 | C7: check later
A8: 预留 | B8: 79508.33 | C8: old
A9: Misc | B9: 87700.45
A10: 预留 | B10: 5415.66 | C10: check later
A11: Misc | B11: 40028.08
A12: 调整 | B12: 50194.24 | C12: old
A13: 杂项 | B13: 69816.15 | C13: 废弃
A14: TBD | B14: 83066.62
A15: 杂项 | B15: 37651.75 | C15: 废弃
A16: 调整 | B16: 69533.87 | C16: old
A17: Misc | B17: 67495.87
A18: 杂项 | B18: 62597.8 | C18: check later
A19: TBD | B19: 57806
A20: TBD | B20: 72028.17 | C20: check later
